Workbook

Sheet Feedsales Statistics
B2: AFMA FEED SALES STATISTICS JAN 2022 - JUL 2022 | D2: JAN 2022 | E2: FEB 2022 | F2: MAR 2022 | G2: APR 2022 | H2: MAY 2022 | I2: JUN 2022 | J2: JUL 2022 | K2: JUL 2021 | L2: M on M % DIFF | M2: TOTAL YTD 2021/2022 | N2: TOTAL YTD 2022/2023 | O2: Y on Y % DIFF
B3: 001 | C3: Dairy Feed | D3: 74183 | E3: 67761 | F3: 75698 | G3: 71227 | H3: 76111 | I3: 74999 | J3: 0 | K3: 76072 | L3: =(J3/K3)-1 | M3: 538286 | N3: ==SUM(D3:J3) | O3: =(N3/M3)-1
B4: % GROWTH M-M | E4: ==(E3/D3)-1 | F4: ==(F3/E3)-1 | G4: ==(G3/F3)-1 | H4: ==(H3/G3)-1 | I4: ==(I3/H3)-1 | J4: ==(J3/I3)-1
B5: 038 | C5: Milk replacement | D5: 0 | E5: 0 | F5: 0 | G5: 0 | H5: 0 | I5: 0 | J5: 0 | K5: 32.6 | L5: =(J5/K5)-1 | M5: 185 | N5: ==SUM(D5:J5) | O5: =(N5/M5)-1
B6: 039 | C6: High Fat Milk Replacement | D6: 0 | E6: 0 | F6: 0 | G6: 0 | H6: 0 | I6: 0 | J6: 0 | K6: 46.38 | L6: =(J6/K6)-1 | M6: 334 | N6: ==SUM(D6:J6) | O6: =(N6/M6)-1
B7: 040 | C7: Calf Starter Meal | D7: 1507.23 | E7: 1375.33 | F7: 1666.21 | G7: 1233.84 | H7: 1392.13 | I7: 1611.24 | J7: 0 | K7: 2010.26 | L7: =(J7/K7)-1 | M7: 12906 | N7: ==SUM(D7:J7) | O7: =(N7/M7)-1
B8: 041 | C8: Calf Growth Meal | D8: 4802.59 | E8: 4265.93 | F8: 5140.84 | G8: 4868.18 | H8: 5209.67 | I8: 5018.61 | J8: 0 | K8: 5261.91 | L8: =(J8/K8)-1 | M8: 32764 | N8: ==SUM(D8:J8) | O8: =(N8/M8)-1
B9: 043 | C9: Complete Dairy Feed | D9: 11482.89 | E9: 10533.67 | F9: 11296.01 | G9: 11036.01 | H9: 13624.91 | I9: 12991.46 | J9: 0 | K9: 11610.89 | L9: =(J9/K9)-1 | M9: 92659 | N9: ==SUM(D9:J9) | O9: =(N9/M9)-1
B10: 045 | C10: Dairy Meal | D10: 56389.84 | E10: 51586.01 | F10: 57594.53 | G10: 54088.78 | H10: 55884.47 | I10: 55378 | J10: 0 | K10: 57110.11 | L10: =(J10/K10)-1 | M10: 399438 | N10: ==SUM(D10:J10) | O10: =(N10/M10)-1
B12: 002 | C12: Beef & Sheep Feed | D12: 53419 | E12: 61292 | F12: 72741 | G12: 54853 | H12: 75379 | I12: 79296 | J12: 0 | K12: 77446 | L12: =(J12/K12)-1 | M12: 505079 | N12: ==SUM(D12:J12) | O12: =(N12/M12)-1
B13: % GROWTH M-M | E13: ==(E12/D12)-1 | F13: ==(F12/E12)-1 | G13: ==(G12/F12)-1 | H13: ==(H12/G12)-1 | I13: ==(I12/H12)-1 | J13: ==(J12/I12)-1
B14: 042 | C14: Cattle Finisher | D14: 869.5 | E14: 790.57 | F14: 797.16 | G14: 738.2 | H14: 1401.55 | I14: 1346.69 | J14: 0 | K14: 1373.69 | L14: =(J14/K14)-1 | M14: 6880 | N14: ==SUM(D14:J14) | O14: =(N14/M14)-1
B15: 135 | C15: Complete Cattle Feed | D15: 6817.67 | E15: 7588.25 | F15: 7325.57 | G15: 8771.13 | H15: 8235.51 | I15: 8416.07 | J15: 0 | K15: 5931.24 | L15: =(J15/K15)-1 | M15: 37144 | N15: ==SUM(D15:J15) | O15: =(N15/M15)-1
B16: 136 | C16: Complete Sheep Feed | D16: 760.99 | E16: 1073.87 | F16: 806 | G16: 537.71 | H16: 545.13 | I16: 434.77 | J16: 0 | K16: 1389.51 | L16: =(J16/K16)-1 | M16: 7317 | N16: ==SUM(D16:J16) | O16: =(N16/M16)-1
B17: 047 | C17: Bull Rations | D17: 84.12 | E17: 201.87 | F17: 148.83 | G17: 183.14 | H17: 254.41 | I17: 85.99 | J17: 0 | K17: 390.2 | L17: =(J17/K17)-1 | M17: 1719 | N17: ==SUM(D17:J17) | O17: =(N17/M17)-1
B18: 140 | C18: Cattle Drought Feed | D18: 208.15 | E18: 135.6 | F18: 350.06 | G18: 184.47 | H18: 414.12 | I18: 165.88 | J18: 0 | K18: 177.32 | L18: =(J18/K18)-1 | M18: 1567 | N18: ==SUM(D18:J18) | O18: =(N18/M18)-1
B19: 141 | C19: Sheep Drought Feed | D19: 234.3 | E19: 102.09 | F19: 206.04 | G19: 216.62 | H19: 243.49 | I19: 435.54 | J19: 0 | K19: 334.11 | L19: =(J19/K19)-1 | M19: 4381 | N19: ==SUM(D19:J19) | O19: =(N19/M19)-1
B20: 049 | C20: Sheep Finisher | D20: 2748.83 | E20: 2910.72 | F20: 3886.35 | G20: 3903.6 | H20: 3938.4 | I20: 4008.78 | J20: 0 | K20: 4087.81 | L20: =(J20/K20)-1 | M20: 27393 | N20: ==SUM(D20:J20) | O20: =(N20/M20)-1
B21: 050 | C21: Ram, Ewe, Lamb Feed | D21: 2827.83 | E21: 3012.97 | F21: 3499.55 | G21: 3179.53 | H21: 4223.97 | I21: 4216.48 | J21: 0 | K21: 3948.44 | L21: =(J21/K21)-1 | M21: 24120 | N21: ==SUM(D21:J21) | O21: =(N21/M21)-1
B22: 051 | C22: Supplement Feeds Beef & Sheep | D22: 38867.95 | E22: 45476.3 | F22: 55721.16 | G22: 37138.2 | H22: 56122.84 | I22: 60185.4 | J22: 0 | K22: 59813.65 | L22: =(J22/K22)-1 | M22: 394558 | N22: ==SUM(D22:J22) | O22: =(N22/M22)-1
B24: 003 | C24: Pig Feed | D24: 39927 | E24: 34833 | F24: 39944 | G24: 37043 | H24: 39929 | I24: 38162 | J24: 0 | K24: 38695 | L24: =(J24/K24)-1 | M24: 241071 | N24: ==SUM(D24:J24) | O24: =(N24/M24)-1
B25: % GROWTH M-M | E25: ==(E24/D24)-1 | F25: ==(F24/E24)-1 | G25: ==(G24/F24)-1 | H25: ==(H24/G24)-1 | I25: ==(I24/H24)-1 | J25: ==(J24/I24)-1
B26: 052 | C26: Pig Creep Meal | D26: 6296.84 | E26: 5201.58 | F26: 5699.33 | G26: 5351.25 | H26: 6548.14 | I26: 6088.51 | J26: 0 | K26: 6100.93 | L26: =(J26/K26)-1 | M26: 35249 | N26: ==SUM(D26:J26) | O26: =(N26/M26)-1
B27: 053 | C27: Pig Growth Meal | D27: 19867.81 | E27: 17835.08 | F27: 21086.74 | G27: 18517.62 | H27: 20278.08 | I27: 19098.43 | J27: 0 | K27: 19164.18 | L27: =(J27/K27)-1 | M27: 118909 | N27: ==SUM(D27:J27) | O27: =(N27/M27)-1
B28: 054 | C28: Pig Finisher Meal | D28: 4112.59 | E28: 3696.88 | F28: 4198.47 | G28: 4659.02 | H28: 4489.55 | I28: 3898.96 | J28: 0 | K28: 3946.9 | L28: =(J28/K28)-1 | M28: 25682 | N28: ==SUM(D28:J28) | O28: =(N28/M28)-1
B29: 055 | C29: Sow & Boar Meal | D29: 9649.32 | E29: 8099.15 | F29: 8959.12 | G29: 8514.83 | H29: 8613.6 | I29: 9075.99 | J29: 0 | K29: 9482.99 | L29: =(J29/K29)-1 | M29: 61231 | N29: ==SUM(D29:J29) | O29: =(N29/M29)-1
B31: 004 | C31: Layer Feed | D31: 79484 | E31: 79627 | F31: 81874 | G31: 77427 | H31: 83787 | I31: 78805 | J31: 0 | K31: 86000 | L31: =(J31/K31)-1 | M31: 580511 | N31: ==SUM(D31:J31) | O31: =(N31/M31)-1
B32: % GROWTH M-M | E32: ==(E31/D31)-1 | F32: ==(F31/E31)-1 | G32: ==(G31/F31)-1 | H32: ==(H31/G31)-1 | I32: ==(I31/H31)-1 | J32: ==(J31/I31)-1
B33: 056 | C33: Poultry Laying Mash | D33: 17272.24 | E33: 16300.13 | F33: 18119.87 | G33: 16655.97 | H33: 17537.32 | I33: 17842.19 | J33: 0 | K33: 19024.36 | L33: =(J33/K33)-1 | M33: 127503 | N33: ==SUM(D33:J33) | O33: =(N33/M33)-1
B34: 057 | C34: All Mash for Layers | D34: 51677.19 | E34: 51239.29 | F34: 53294.34 | G34: 50398.54 | H34: 54441.31 | I34: 48673.23 | J34: 0 | K34: 53399.28 | L34: =(J34/K34)-1 | M34: 363539 | N34: ==SUM(D34:J34) | O34: =(N34/M34)-1
B35: 058 | C35: Poultry Growing Mash | D35: 5074.39 | E35: 4150.45 | F35: 4512.09 | G35: 4293.52 | H35: 5123.59 | I35: 5612.88 | J35: 0 | K35: 5527.48 | L35: =(J35/K35)-1 | M35: 41295 | N35: ==SUM(D35:J35) | O35: =(N35/M35)-1
B36: 059 | C36: Pullet Developer Mash | D36: 2606.28 | E36: 2325.77 | F36: 3032.21 | G36: 3169.97 | H36: 3620.28 | I36: 3531.61 | J36: 0 | K36: 3457.1 | L36: =(J36/K36)-1 | M36: 22169 | N36: ==SUM(D36:J36) | O36: =(N36/M36)-1
B37: 060 | C37: Chicken Starter Mash | D37: 2854.31 | E37: 5611.64 | F37: 2915.84 | G37: 2909.04 | H37: 3064.62 | I37: 3144.91 | J37: 0 | K37: 4591.91 | L37: =(J37/K37)-1 | M37: 26006 | N37: ==SUM(D37:J37) | O37: =(N37/M37)-1
B39: 005 | C39: Broiler Feed | D39: 239231 | E39: 223358 | F39: 256789 | G39: 233182 | H39: 255454 | I39: 256174 | J39: 0 | K39: 237085 | L39: =(J39/K39)-1 | M39: 1722694 | N39: ==SUM(D39:J39) | O39: =(N39/M39)-1
B40: % GROWTH M-M | E40: ==(E39/D39)-1 | F40: ==(F39/E39)-1 | G40: ==(G39/F39)-1 | H40: ==(H39/G39)-1 | I40: ==(I39/H39)-1 | J40: ==(J39/I39)-1
B41: 061 | C41: Broiler All Mash | D41: 178.27 | E41: 103.2 | F41: 150.1 | G41: 170.31 | H41: 166.22 | I41: 117.91 | J41: 0 | K41: 4519.2 | L41: =(J41/K41)-1 | M41: 10077 | N41: ==SUM(D41:J41) | O41: =(N41/M41)-1
B42: 062 | C42: Broiler Pre-starter Mash | D42: 15775.68 | E42: 18052.5 | F42: 16987.37 | G42: 17375.29 | H42: 20362.95 | I42: 20522.55 | J42: 0 | K42: 13477.56 | L42: =(J42/K42)-1 | M42: 92544 | N42: ==SUM(D42:J42) | O42: =(N42/M42)-1
B43: 063 | C43: Broiler Starter Mash | D43: 52041.86 | E43: 49430.36 | F43: 53941.24 | G43: 52293.87 | H43: 57432.94 | I43: 56569.3 | J43: 0 | K43: 53687.85 | L43: =(J43/K43)-1 | M43: 399844 | N43: ==SUM(D43:J43) | O43: =(N43/M43)-1
B44: 064 | C44: Broiler Grower Mash | D44: 94657.06 | E44: 83983.02 | F44: 98024.9 | G44: 86326.52 | H44: 92309.39 | I44: 92320.83 | J44: 0 | K44: 89033.97 | L44: =(J44/K44)-1 | M44: 653129 | N44: ==SUM(D44:J44) | O44: =(N44/M44)-1
B45: 065 | C45: Broiler Finisher Mash | D45: 55290.34 | E45: 50573.58 | F45: 62291.09 | G45: 53577.25 | H45: 58543.12 | I45: 61276.08 | J45: 0 | K45: 55025.86 | L45: =(J45/K45)-1 | M45: 398154 | N45: ==SUM(D45:J45) | O45: =(N45/M45)-1
...

Sheet Raw Material Statistics
B2: AFMA - RAW MATERIAL USAGE JAN 2022 - JUL 2022 | D2: TOTAL TONS | E2: % MAKEUP IN FEEDS | F2: JAN 2022 | G2: FEB 2022 | H2: MAR 2022 | I2: APR 2022 | J2: MAY 2022 | K2: JUN 2022 | L2: JUL 2022
B3: 606 | C3: Additives | D3: ==SUM(F3:L3) | E3: ==(D3/D111) | F3: 351.97 | G3: 291.91 | H3: 268.58 | I3: 142.96 | J3: 140.97 | K3: 195.92 | L3: 0
B4: 607 | C4: Amino Acids (not listed) | D4: ==SUM(F4:L4) | E4: ==(D4/D111) | F4: 101.72 | G4: 101.16 | H4: 128.75 | I4: 102.25 | J4: 106.55 | K4: 164.54 | L4: 0
B5: 613 | C5: Ammonium chloride | D5: ==SUM(F5:L5) | E5: ==(D5/D111) | F5: 177.4 | G5: 156.77 | H5: 193.71 | I5: 97.32 | J5: 212.47 | K5: 182.94 | L5: 0
B6: 553 | C6: Ammonium sulphate | D6: ==SUM(F6:L6) | E6: ==(D6/D111) | F6: 334.31 | G6: 556.88 | H6: 713.93 | I6: 635.31 | J6: 768.03 | K6: 781.32 | L6: 0
B7: 557 | C7: Apple pomace | D7: ==SUM(F7:L7) | E7: ==(D7/D111) | F7: 3.05 | G7: 3.04 | H7: 0.05 | I7: 3.06 | J7: 0.06 | K7: 3.07 | L7: 0
B8: 524 | C8: Bagasse | D8: ==SUM(F8:L8) | E8: ==(D8/D111) | F8: 6139 | G8: 7284 | H8: 9179.1 | I8: 5370 | J8: 8959.2 | K8: 11043.1 | L8: 0
B9: 551 | C9: Barley (All) | D9: ==SUM(F9:L9) | E9: ==(D9/D111) | F9: 8041.65 | G9: 5360.08 | H9: 4525.7 | I9: 3319.41 | J9: 3379.19 | K9: 2158.53 | L9: 0
B10: 501 | C10: Blended oil | D10: ==SUM(F10:L10) | E10: ==(D10/D111) | F10: 2793.11 | G10: 2596.56 | H10: 2808.16 | I10: 2718.17 | J10: 2900.93 | K10: 2227.31 | L10: 0
B11: 619 | C11: Blood meal (bovine) - Imported | D11: ==SUM(F11:L11) | E11: ==(D11/D111) | F11: 0 | G11: 0 | H11: 0 | I11: 0 | J11: 0 | K11: 0 | L11: 0
B12: 618 | C12: Blood meal (bovine) - Local | D12: ==SUM(F12:L12) | E12: ==(D12/D111) | F12: 9.73 | G12: 15 | H12: 20.5 | I12: 4 | J12: 4 | K12: 10 | L12: 0
B13: 621 | C13: Blood meal (porcine) - Imported | D13: ==SUM(F13:L13) | E13: ==(D13/D111) | F13: 0 | G13: 0 | H13: 0 | I13: 0 | J13: 0 | K13: 0 | L13: 0
B14: 620 | C14: Blood meal (porcine) - Local | D14: ==SUM(F14:L14) | E14: ==(D14/D111) | F14: 0 | G14: 0 | H14: 0 | I14: 0 | J14: 0 | K14: 0 | L14: 0
B15: 503 | C15: Blood meal (poultry) - Imported | D15: ==SUM(F15:L15) | E15: ==(D15/D111) | F15: 701.66 | G15: 769.03 | H15: 660.92 | I15: 713.4 | J15: 835.18 | K15: 637.44 | L15: 0
B16: 610 | C16: Blood meal (poultry) - Local | D16: ==SUM(F16:L16) | E16: ==(D16/D111) | F16: 1.87 | G16: 0.04 | H16: 34 | I16: 2.91 | J16: 6.1 | K16: 0.1 | L16: 0
B17: 504 | C17: Brewers grain | D17: ==SUM(F17:L17) | E17: ==(D17/D111) | F17: 904 | G17: 843.56 | H17: 1108.55 | I17: 572.97 | J17: 751.36 | K17: 730.11 | L17: 0
B18: 558 | C18: Canola fullfat | D18: ==SUM(F18:L18) | E18: ==(D18/D111) | F18: 0 | G18: 36 | H18: 0 | I18: 28 | J18: 0 | K18: 0 | L18: 0
B19: 614 | C19: Canola oil | D19: ==SUM(F19:L19) | E19: ==(D19/D111) | F19: 0 | G19: 25 | H19: 107 | I19: 25 | J19: 34 | K19: 29.62 | L19: 0
B20: 566 | C20: Canola oilcake - Imported | D20: ==SUM(F20:L20) | E20: ==(D20/D111) | F20: 0 | G20: 0 | H20: 0 | I20: 0 | J20: 35 | K20: 30 | L20: 0
B21: 565 | C21: Canola oilcake - Local | D21: ==SUM(F21:L21) | E21: ==(D21/D111) | F21: 2306.8 | G21: 2246.3 | H21: 2647.28 | I21: 2876.48 | J21: 2868.01 | K21: 2537.75 | L21: 0
B22: 511 | C22: Carcass Meal | D22: ==SUM(F22:L22) | E22: ==(D22/D111) | F22: 0 | G22: 0 | H22: 0 | I22: 0 | J22: 0 | K22: 0 | L22: 0
B23: 525 | C23: Cassava meal | D23: ==SUM(F23:L23) | E23: ==(D23/D111) | F23: 0 | G23: 0 | H23: 0 | I23: 0 | J23: 0 | K23: 0 | L23: 0
B24: 700 | C24: Choline chloride | D24: ==SUM(F24:L24) | E24: ==(D24/D111) | F24: 14.9 | G24: 19.53 | H24: 14.75 | I24: 15.21 | J24: 18.86 | K24: 35.75 | L24: 0
B25: 526 | C25: Citrus meal | D25: ==SUM(F25:L25) | E25: ==(D25/D111) | F25: 82.3 | G25: 70.91 | H25: 116.69 | I25: 116.3 | J25: 118.09 | K25: 113.99 | L25: 0
B26: 563 | C26: CMS | D26: ==SUM(F26:L26) | E26: ==(D26/D111) | F26: 1055.15 | G26: 1012.3 | H26: 1052.18 | I26: 900.5 | J26: 2277.83 | K26: 1731.29 | L26: 0
B27: 582 | C27: Copra oilcake products | D27: ==SUM(F27:L27) | E27: ==(D27/D111) | F27: 16.24 | G27: 11.45 | H27: 1.53 | I27: 0 | J27: 0 | K27: 0 | L27: 0
B28: 568 | C28: Cotton Oilcake (Imported) | D28: ==SUM(F28:L28) | E28: ==(D28/D111) | F28: 893.98 | G28: 886.95 | H28: 851.57 | I28: 508.77 | J28: 1591.21 | K28: 1579.78 | L28: 0
B29: 567 | C29: Cotton Oilcake (Local) | D29: ==SUM(F29:L29) | E29: ==(D29/D111) | F29: 75 | G29: 164 | H29: 560.9 | I29: 164.2 | J29: 205 | K29: 196 | L29: 0
B30: 570 | C30: Cotton Seed (Imported) | D30: ==SUM(F30:L30) | E30: ==(D30/D111) | F30: 0 | G30: 0 | H30: 0 | I30: 0 | J30: 0 | K30: 0 | L30: 0
B31: 569 | C31: Cotton Seed (Local) | D31: ==SUM(F31:L31) | E31: ==(D31/D111) | F31: 673.48 | G31: 530.65 | H31: 570.1 | I31: 527.5 | J31: 601.95 | K31: 555.6 | L31: 0
B32: 549 | C32: Defatted Maize Germ | D32: ==SUM(F32:L32) | E32: ==(D32/D111) | F32: 987.76 | G32: 869.17 | H32: 887.05 | I32: 991.58 | J32: 981.89 | K32: 595.14 | L32: 0
B33: 552 | C33: Dicalcium Phosphate | D33: ==SUM(F33:L33) | E33: ==(D33/D111) | F33: 294.7 | G33: 142.58 | H33: 75.72 | I33: 120.1 | J33: 219.22 | K33: 213.63 | L33: 0
B34: 521 | C34: Fat / Vet (TALLOW) | D34: ==SUM(F34:L34) | E34: ==(D34/D111) | F34: 355.61 | G34: 153.86 | H34: 143.67 | I34: 126.6 | J34: 165.01 | K34: 198.38 | L34: 0
B35: 520 | C35: Feather Meal - Local | D35: ==SUM(F35:L35) | E35: ==(D35/D111) | F35: 1502.71 | G35: 948.47 | H35: 1414.49 | I35: 1488.75 | J35: 1571.88 | K35: 1638.05 | L35: 0
B36: 528 | C36: Feed Wheat | D36: ==SUM(F36:L36) | E36: ==(D36/D111) | F36: 41 | G36: 61 | H36: 52 | I36: 62 | J36: 76 | K36: 0 | L36: 0
B37: 572 | C37: Fish Meal (Imported) | D37: ==SUM(F37:L37) | E37: ==(D37/D111) | F37: 14.95 | G37: 23.3 | H37: 0 | I37: 13 | J37: 7 | K37: 11.7 | L37: 0
B38: 571 | C38: Fish Meal (Local) | D38: ==SUM(F38:L38) | E38: ==(D38/D111) | F38: 1096.74 | G38: 951.44 | H38: 1221.05 | I38: 1016.49 | J38: 1136.75 | K38: 1158.19 | L38: 0
B39: 529 | C39: Groundnut Hay | D39: ==SUM(F39:L39) | E39: ==(D39/D111) | F39: 55.99 | G39: 39.29 | H39: 98.59 | I39: 88.72 | J39: 250.89 | K39: 334 | L39: 0
B40: 574 | C40: Groundnut Oilcake (Imported) | D40: ==SUM(F40:L40) | E40: ==(D40/D111) | F40: 0 | G40: 0 | H40: 0 | I40: 0 | J40: 0 | K40: 0 | L40: 0
B41: 573 | C41: Groundnut Oilcake (Local) | D41: ==SUM(F41:L41) | E41: ==(D41/D111) | F41: 22.29 | G41: 0 | H41: 0 | I41: 0 | J41: 0 | K41: 0 | L41: 0
...

Sheet Raw Material Usage
B2: AFMA - RAW MATERIAL USAGE JAN 2022 - JUL 2022
B4: OILCAKE USAGE | C4: OILCAKE USAGE | D4: OILCAKE USAGE | E4: OILCAKE USAGE | F4: OILCAKE USAGE | G4: OILCAKE USAGE
B6: 2022/2022 | C6: 2022/2022 | D6: 2022/2022 | F6: 2021/2021 | G6: 2021/2021
B8: RAW MATERIAL | C8: TONS | D8: % MAKEUP IN FEEDS | F8: TONS | G8: % MAKEUP IN FEEDS
B9: Canola Oilcake | C9: 15548 | D9: =C9/'Raw Material Statistics'!D111 | F9: 19413 | G9: =F9/'Raw Material Statistics'!D111
B10: Copra and Palm Kernel | C10: 1682 | D10: =C10/'Raw Material Statistics'!D111 | F10: 2904 | G10: =F10/'Raw Material Statistics'!D111
B11: Cotton Oilcake | C11: 7677 | D11: =C11/'Raw Material Statistics'!D111 | F11: 2344 | G11: =F11/'Raw Material Statistics'!D111
B12: Fullfat Canola | C12: 64 | D12: =C12/'Raw Material Statistics'!D111 | F12: 211 | G12: =F12/'Raw Material Statistics'!D111
B13: Fullfat Cotton | C13: 3459 | D13: =C13/'Raw Material Statistics'!D111 | F13: 3560 | G13: =F13/'Raw Material Statistics'!D111
B14: Fullfat Soya | C14: 64739 | D14: =C14/'Raw Material Statistics'!D111 | F14: 60258 | G14: =F14/'Raw Material Statistics'!D111
B15: Groundnut Oilcake | C15: 22 | D15: =C15/'Raw Material Statistics'!D111 | F15: 0 | G15: =F15/'Raw Material Statistics'!D111
B16: Maize Germ Oilcake | C16: 0 | D16: =C16/'Raw Material Statistics'!D111 | F16: 1739 | G16: =F16/'Raw Material Statistics'!D111
B17: Soya Oilcake | C17: 506619 | D17: =C17/'Raw Material Statistics'!D111 | F17: 609126 | G17: =F17/'Raw Material Statistics'!D111
B18: Sunflower Oilcake | C18: 119892 | D18: =C18/'Raw Material Statistics'!D111 | F18: 138391 | G18: =F18/'Raw Material Statistics'!D111
B19: TOTAL OILCAKE USED (TONS) | C19: ==SUM(C9:C18) | D19: ==SUM(D9:D18) | F19: ==SUM(F9:F18) | G19: ==SUM(G9:G18)
B22: MAIZE USAGE | C22: MAIZE USAGE | D22: MAIZE USAGE | E22: MAIZE USAGE | F22: MAIZE USAGE | G22: MAIZE USAGE
B24: 2022/2022 | C24: 2022/2022 | D24: 2022/2022 | F24: 2021/2021 | G24: 2021/2021
B26: RAW MATERIAL | C26: TONS | D26: % MAKEUP IN FEEDS | F26: TONS | G26: % MAKEUP IN FEEDS
B27: Defatted Maize Germ Meal | C27: 5313 | D27: =C27/'Raw Material Statistics'!D111 | F27: 6394 | G27: =F27/'Raw Material Statistics'!D111
B28: Hominy Chop | C28: 58399 | D28: =C28/'Raw Material Statistics'!D111 | F28: 68653 | G28: =F28/'Raw Material Statistics'!D111
B29: Maize | C29: 1654198 | D29: =C29/'Raw Material Statistics'!D111 | F29: 1940927 | G29: =F29/'Raw Material Statistics'!D111
B30: Maize Germ Meal | C30: 3712 | D30: =C30/'Raw Material Statistics'!D111 | F30: 18454 | G30: =F30/'Raw Material Statistics'!D111
B31: Maize Germ Oilcake | C31: 0 | D31: =C31/'Raw Material Statistics'!D111 | F31: 1739 | G31: =F31/'Raw Material Statistics'!D111
B32: Maize Gluten Meal (20%) | C32: 32295 | D32: =C32/'Raw Material Statistics'!D111 | F32: 38569 | G32: =F32/'Raw Material Statistics'!D111
B33: Maize Gluten Meal (60%) | C33: 8099 | D33: =C33/'Raw Material Statistics'!D111 | F33: 6690 | G33: =F33/'Raw Material Statistics'!D111
B34: Maize Meal | C34: 9233 | D34: =C34/'Raw Material Statistics'!D111 | F34: 7327 | G34: =F34/'Raw Material Statistics'!D111
B35: Maize Screenings | C35: 3888 | D35: =C35/'Raw Material Statistics'!D111 | F35: 4369 | G35: =F35/'Raw Material Statistics'!D111
B36: TOTAL MAIZE USED (TONS) | C36: ==SUM(C27:C35) | D36: ==SUM(D27:D35) | F36: ==SUM(F27:F35) | G36: ==SUM(G27:G35)
B38: RAW MATERIAL USAGE AND FEED PRODUCTION | C38: RAW MATERIAL USAGE AND FEED PRODUCTION | D38: RAW MATERIAL USAGE AND FEED PRODUCTION
B39: MAIZE PRODUCT USAGE | C39: ==C36 | D39: ==D36
B40: FISHMEAL USAGE | C40: 6651 | D40: =(C40/'Raw Material Statistics'!D111)
B41: OILCAKE USAGE | C41: ==C19 | D41: ==D19
B42: TOTAL FEED SALES | C42: ='Feedsales Statistics'!N113
